Workbook

Sheet 0_Hướng dẫn
A1: CS12 · Đánh giá sản phẩm AI · Bài tập buổi sáng 16/10/2026
A2: AI in Action · Track 1 · Khóa 4. Bài tập đi kèm bộ slide "AI Evaluation" của chị Mai Anh Nguyen (66 trang). Slide của chị Mai Anh giữ nguyên; file này là phần thực hành.
A4: Luật chơi: CHỈ điền vào ô màu VÀNG. Ô màu XANH LÁ NHẠT tự tính và đã khoá. Cột "Kiểm tra" báo Đúng hoặc Chưa đúng ngay khi điền.
A5: Bài 1–5 (10–12 phút mỗi bài, sau mỗi phần trình chiếu): làm CÁ NHÂN, không tính điểm, để tự biết mình đã hiểu chưa. Chưa đúng: đọc lại trang slide ghi ở cột "Trang", sửa, rồi hỏi trong khung chat.
A6: Xưởng (50 phút, cuối buổi): làm THEO NHÓM 4–6 người trong phòng nhóm. Có chấm điểm theo trang "Thang điểm". Mỗi nhóm nộp 1 file.
A7: Mọi bài dùng chung một tình huống giả định: trợ lý đổi trả của cửa hàng Mộc Store. Đọc trang "0_Tình huống" trước Bài 1 (3 phút).
A8: Tên file nộp: [Nhom]_CS12.xlsx · Nộp lên VLearn trước 13:00 ngày 16/10. Chỉ cần trang Xưởng đã điền; Bài 1–5 điền hay không đều được.
A9: Tỷ lệ gõ kèm dấu % (ví dụ 84%). Số thập phân dùng dấu phẩy hay dấu chấm tùy máy; nếu ô báo "Gõ một số" thì đổi dấu.
A10: Đáp án và giải thích: giảng viên chiếu ngay sau mỗi bài; bản đáp án đầy đủ gửi sau buổi học.
A12: Lịch buổi sáng 16/10 (trực tuyến)
A13: Giờ | B13: Hoạt động | C13: Nội dung | D13: Thời lượng
A14: 09:00–09:05 | B14: Mở đầu | C14: Chào lớp; giới thiệu tình huống Mộc Store (slide bài tập 1–9); trợ giảng gửi đường dẫn tài liệu
A15: 09:05–09:20 | B15: Trình chiếu | C15: Trang 1–12: khoảng trống đánh giá, tình huống Notion AI
A16: 09:20–09:40 | B16: Trình chiếu | C16: Phần 01 · trang 13–23: vòng đời đánh giá, báo cáo, tài liệu yêu cầu
A17: 09:40–09:50 | B17: Bài 1 | C17: Đọc báo cáo đánh giá và thu hẹp phạm vi | D17: 10 phút
A18: 09:50–10:05 | B18: Trình chiếu | C18: Phần 02 · trang 24–30: phủ ca, lưới đầu vào, ngân hàng tình huống
A19: 10:05–10:17 | B19: Bài 2 | C19: Phủ ca và chọn tình huống | D19: 12 phút
A20: 10:17–10:27 | B20: Nghỉ | C20: Nghỉ 10 phút
A21: 10:27–10:40 | B21: Trình chiếu | C21: Phần 03 · trang 31–36: đọc vết thực thi, mã lỗi
A22: 10:40–10:50 | B22: Bài 3 | C22: Đọc vết thực thi, tìm bước sai đầu tiên | D22: 10 phút
A23: 10:50–11:12 | B23: Trình chiếu | C23: Phần 04–05 · trang 37–50: chấm tự động, chấm bằng mã lệnh
A24: 11:12–11:22 | B24: Bài 4 | C24: Chọn cách chấm và ra kết luận | D24: 10 phút
A25: 11:22–11:32 | B25: Nghỉ | C25: Nghỉ 10 phút
A26: 11:32–11:48 | B26: Trình chiếu | C26: Phần 06 · trang 51–59: hiệu chỉnh giám khảo AI
A27: 11:48–11:58 | B27: Bài 5 | C27: Hiệu chỉnh giám khảo AI | D27: 10 phút
A28: 11:58–12:06 | B28: Trình chiếu | C28: Phần 07 · trang 60–66: đưa chuyên gia vào vòng lặp, tổng kết
A29: 12:06–12:56 | B29: Xưởng | C29: Hướng dẫn 4 phút; làm trong phòng nhóm 12:10–12:53; soát và nộp 12:53–12:56 (nhóm 4–6 người, có chấm điểm) | D29: 50 phút
A30: 12:56–13:00 | B30: Nộp bài | C30: Nộp file lên VLearn, kết thúc buổi sáng

Sheet 0_Tình huống
A1: Hồ sơ tình huống · Trợ lý đổi trả của Mộc Store (giả định)
A2: Mộc Store là cửa hàng thời trang bán online (áo, quần, giày) qua website và Zalo. Tình huống giả định, dùng cho toàn bộ buổi sáng.
A3: Trợ lý AI "Mộc" trả lời tin nhắn về đổi hàng, trả hàng và tình trạng đơn. Khoảng 300 tin nhắn loại này mỗi ngày.
A4: Chuyên gia: chị Ngân, trưởng nhóm chăm sóc khách hàng, 6 năm kinh nghiệm. Chị là người định nghĩa thế nào là "đạt".
A6: Chính sách đổi trả
A7: Mã | B7: Nội dung | C7: Quy định
A8: CS-1 | B8: Đổi size hoặc màu | C8: Trong 7 ngày kể từ ngày nhận hàng, hàng còn tem mác. Miễn phí đổi lần đầu.
A9: CS-2 | B9: Trả hàng, hoàn tiền | C9: Trong 7 ngày kể từ ngày nhận hàng. Tiền hoàn trong 3–5 ngày làm việc sau khi kho nhận lại hàng.
A10: CS-3 | B10: Hàng lỗi (bong keo, rách, sai mẫu) | C10: Trong 30 ngày kể từ ngày nhận hàng. Trợ lý chuyển nhân viên xử lý, không tự hứa đền bù.
A11: CS-4 | B11: Tra cứu trước khi hứa | C11: Trước khi xác nhận đổi, trả hay hoàn tiền: phải tra cứu đơn (ngày nhận, trạng thái).
A12: CS-5 | B12: Thiếu mã đơn | C12: Hỏi mã đơn hoặc số điện thoại đặt hàng. Không đoán đơn.
A13: CS-6 | B13: Khách muốn gặp người | C13: Khách yêu cầu gặp nhân viên, hoặc khiếu nại hàng lỗi: chuyển nhân viên.
A15: 4 nhãn ý định (giống trang 16): Đổi hàng · Trả hàng · Tra cứu đơn · Cần làm rõ
A16: Tin khiếu nại hàng lỗi gắn nhãn Trả hàng kèm cờ "hàng lỗi: có". Tin không rõ đơn nào hoặc không rõ muốn gì gắn nhãn Cần làm rõ.
A18: Công cụ trợ lý gọi được
B19: Công cụ | C19: Làm gì
A20: 1 | B20: tra_cuu_don | C20: tra đơn theo mã đơn hoặc số điện thoại; trả về ngày nhận hàng và trạng thái
A21: 2 | B21: tao_yeu_cau_doi_tra | C21: tạo yêu cầu đổi hoặc trả cho một mã đơn
A22: 3 | B22: chuyen_nhan_vien | C22: chuyển cuộc trò chuyện cho nhân viên, kèm lý do
A23: Chưa có công cụ tra tồn kho (dùng ở Bài 4).
A25: Mã lỗi dùng ở Bài 3 và Xưởng (trang 35)
B26: Mã lỗi | C26: Nghĩa
A27: 1 | B27: wrong_intent | C27: Hiểu sai nhu cầu chính của khách
A28: 2 | B28: missing_lookup | C28: Không tra cứu dữ liệu trước khi trả lời
A29: 3 | B29: premature_commit | C29: Hứa kết quả khi chưa đủ điều kiện
A30: 4 | B30: missing_escalation | C30: Không chuyển nhân viên khi vượt thẩm quyền
A31: 5 | B31: no_next_step | C31: Đúng chính sách nhưng thiếu bước tiếp theo
A33: Bảng đối chiếu từ ngữ: slide của chị Mai Anh ↔ bài tập
B34: Trên slide | C34: Trong bài tập
A35: 1 | B35: eval, evals | C35: bài đánh giá
A36: 2 | B36: reference dataset, dataset | C36: bộ đề chuẩn, bộ đề
A37: 3 | B37: golden outputs | C37: đáp án mẫu
A38: 4 | B38: baseline · candidate | C38: bản đang chạy · bản mới
A39: 5 | B39: pass rate | C39: tỷ lệ đạt
A40: 6 | B40: quality gate, threshold | C40: cổng chất lượng, ngưỡng
A41: 7 | B41: regression | C41: hồi quy: ca trước đạt, nay trượt
A42: 8 | B42: slice | C42: nhóm (cắt theo một thuộc tính)
A43: 9 | B43: unit of AI work | C43: đơn vị công việc AI
A44: 10 | B44: dimension | C44: chiều
A45: 11 | B45: User Input Grid | C45: lưới đầu vào
...

Sheet Bài 1
A1: Bài 1 · Đọc báo cáo đánh giá và thu hẹp phạm vi (10 phút) · sau Phần 01 · trang 13–23
A2: Làm cá nhân, không tính điểm. Điền ô vàng ở cột C; cột D tự báo kết quả.
A4: Nhóm vừa đổi câu lệnh của trợ lý Mộc (v1.3 → v1.4) và chạy lại trên bộ đề chuẩn 50 tin nhắn đã có nhãn đúng.
A5: Cổng chất lượng chốt trước khi chạy: tỷ lệ đúng tổng từ 82% trở lên.
A6: Có 3 tin "hồi quy" (v1.3 đúng, v1.4 sai), cả 3 nằm ở nhóm Tra cứu đơn.
A8: Nhóm ý định | C8: Số tin trong bộ đề | D8: v1.3 đúng (bản đang chạy) | E8: v1.4 đúng (bản mới)
A9: Đổi hàng | C9: 20 | D9: 16 | E9: 19
A10: Trả hàng | C10: 20 | D10: 15 | E10: 17
A11: Tra cứu đơn | C11: 10 | D11: 9 | E11: 6
A12: Tổng | C12: 50 | D12: 40 | E12: 42
A14: Câu 1.6: A. Phát hành ngay: tổng tăng 4 điểm và đã qua cổng. · B. Chưa phát hành: mở đọc 3 tin hồi quy ở nhóm Tra cứu đơn, hiểu vì sao sai rồi mới quyết định. · C. Quay về v1.3: tổng chỉ tăng 2 tin, chắc chắn là nhiễu.
A15: Câu 1.8: A. Làm khách hài lòng hơn mỗi khi đổi trả. · B. Đọc 1 tin nhắn đổi trả → gắn đúng 1 trong 4 nhãn ý định, dưới 2 giây. · C. Trả lời mọi câu hỏi của khách về đơn hàng và chính sách.
A16: Câu 1.9: Trục 1. Tách theo việc · Trục 2. Tách theo điều kiện đầu vào · Trục 3. Tách theo mức tự chủ
A18: Câu | B18: Đề | C18: Trả lời | D18: Kiểm tra | E18: Trang
A19: 1.1 | B19: Trên bộ 50 tin, 1 tin đổi kết quả làm tỷ lệ đúng thay đổi bao nhiêu điểm phần trăm? (gõ một số) | C19: 2 | D19: =IF(C19="","",IF(ISNUMBER(C19),IF(ABS(C19-2)<=0.01,"Đúng","Chưa đúng"),"Gõ một số")) -> Đúng | E19: 18
A20: 1.2 | B20: Tỷ lệ đúng tổng của v1.4 là bao nhiêu? (gõ kèm %) | C20: 0.84 | D20: =IF(C20="","",IF(ISNUMBER(C20),IF(OR(ABS(C20-0.84)<=0.006,ABS(C20-84)<=0.6),"Đúng","Chưa đúng"),"Gõ một số")) -> Đúng | E20: 18
A21: 1.3 | B21: v1.4 có qua cổng chất lượng (≥ 82%) không? (chọn: Có / Không) | C21: Có | D21: =IF(C21="","",IF(C21="Có","Đúng","Chưa đúng")) -> Đúng | E21: 18
A22: 1.4 | B22: Tỷ lệ đúng của nhóm Tra cứu đơn ở v1.4 là bao nhiêu? (gõ kèm %) | C22: 0.6 | D22: =IF(C22="","",IF(ISNUMBER(C22),IF(OR(ABS(C22-0.6)<=0.006,ABS(C22-60)<=0.6),"Đúng","Chưa đúng"),"Gõ một số")) -> Đúng | E22: 18
A23: 1.5 | B23: Nhóm Tra cứu đơn tụt bao nhiêu điểm phần trăm? (gõ một số) | C23: 30 | D23: =IF(C23="","",IF(ISNUMBER(C23),IF(ABS(C23-30)<=0.01,"Đúng","Chưa đúng"),"Gõ một số")) -> Đúng | E23: 18
A24: 1.6 | B24: Kết luận nào đúng? | C24: B | D24: =IF(C24="","",IF(C24="B","Đúng","Chưa đúng")) -> Đúng | E24: 18
A25: 1.7 | B25: Muốn tin một khoảng chênh 3 điểm phần trăm là thật (độ tin 95%), cần khoảng bao nhiêu ca? (chọn: Khoảng 100 ca / Khoảng 1.000 ca / Khoảng 10.000 ca) | C25: Khoảng 1.000 ca | D25: =IF(C25="","",IF(C25="Khoảng 1.000 ca","Đúng","Chưa đúng")) -> Đúng | E25: 18
A26: 1.8 | B26: Mục tiêu "Dùng AI để chăm sóc khách đổi trả tốt hơn" quá rộng. Câu nào là đơn vị công việc AI đo được? | C26: B | D26: =IF(C26="","",IF(C26="B","Đúng","Chưa đúng")) -> Đúng | E26: 23
A27: 1.9 | B27: Tách "tin nhắn rõ ràng" và "tin nhắn mơ hồ" để đặt kỳ vọng khác nhau (tin mơ hồ thì hỏi lại) là thu hẹp theo trục nào? | C27: Trục 2 | D27: =IF(C27="","",IF(C27="Trục 2","Đúng","Chưa đúng")) -> Đúng | E27: 23
A29: Số câu đúng | C29: =COUNTIF(D19:D27,"Đúng") -> 9 | D29: / 9 câu

Sheet Bài 2
A1: Bài 2 · Phủ ca và chọn tình huống (12 phút) · sau Phần 02 · trang 24–30
A2: Làm cá nhân, không tính điểm. Điền ô vàng ở cột C; cột D tự báo kết quả.
A4: Phép thử chiều (trang 26): đổi giá trị của một thuộc tính trong tin nhắn → hành vi đúng của trợ lý có đổi không?
A5: Có đổi → là một chiều của lưới. Không đổi → chỉ là cách diễn đạt, để AI viết lại, không tốn một chiều.
A7: Câu 2.14: A. Nhờ AI tạo 50 câu kiểm thử là đủ phủ. · B. Người chọn ô cần thử trên lưới; AI chỉ viết thêm cách diễn đạt cho từng ô. · C. Càng nhiều dòng thì bộ đề càng phủ tốt.
A9: Câu | B9: Đề | C9: Trả lời | D9: Kiểm tra | E9: Trang
A10: 2.1 | B10: Khách viết có dấu hay không dấu. Đây có phải một chiều? (chọn: Có / Không) | C10: Không | D10: =IF(C10="","",IF(C10="Không","Đúng","Chưa đúng")) -> Đúng | E10: 26
A11: 2.2 | B11: Tin nhắn có mã đơn hay không có mã đơn. Đây có phải một chiều? (chọn: Có / Không) | C11: Có | D11: =IF(C11="","",IF(C11="Có","Đúng","Chưa đúng")) -> Đúng | E11: 26
A12: 2.3 | B12: Khách nói lịch sự hay cộc lốc. Đây có phải một chiều? (chọn: Có / Không) | C12: Không | D12: =IF(C12="","",IF(C12="Không","Đúng","Chưa đúng")) -> Đúng | E12: 26
A13: 2.4 | B13: Đơn còn trong 7 ngày, đã quá 7 ngày, hay là hàng lỗi trong 30 ngày. Đây có phải một chiều? (chọn: Có / Không) | C13: Có | D13: =IF(C13="","",IF(C13="Có","Đúng","Chưa đúng")) -> Đúng | E13: 26
A14: 2.5 | B14: Tin nhắn có 1 ý hay 2 ý (một đơn muốn đổi, một đơn muốn trả). Đây có phải một chiều? (chọn: Có / Không) | C14: Có | D14: =IF(C14="","",IF(C14="Có","Đúng","Chưa đúng")) -> Đúng | E14: 26
A15: 2.6 | B15: Tin nhắn dài hay ngắn (cùng nội dung). Đây có phải một chiều? (chọn: Có / Không) | C15: Không | D15: =IF(C15="","",IF(C15="Không","Đúng","Chưa đúng")) -> Đúng | E15: 26
A16: 2.7 | B16: Nhóm chọn 3 chiều: Ý định (4 giá trị) × Độ đủ thông tin (3 giá trị: đủ, thiếu mã đơn, mơ hồ) × Tình trạng đơn (3 giá trị: trong hạn, quá hạn, hàng lỗi). Có bao nhiêu tổ hợp? | C16: 36 | D16: =IF(C16="","",IF(ISNUMBER(C16),IF(ABS(C16-36)<=0.01,"Đúng","Chưa đúng"),"Gõ một số")) -> Đúng | E16: 29
A17: 2.8 | B17: Nhóm loại 12 tổ hợp phi lý. Còn lại bao nhiêu tổ hợp? | C17: 24 | D17: =IF(C17="","",IF(ISNUMBER(C17),IF(ABS(C17-24)<=0.01,"Đúng","Chưa đúng"),"Gõ một số")) -> Đúng | E17: 29
A18: 2.9 | B18: Từ 24 tổ hợp, nhóm chọn 16 tình huống đáng thử; mỗi tình huống viết 3 cách diễn đạt. Bộ đề có bao nhiêu đầu vào? | C18: 48 | D18: =IF(C18="","",IF(ISNUMBER(C18),IF(ABS(C18-48)<=0.01,"Đúng","Chưa đúng"),"Gõ một số")) -> Đúng | E18: 29
A19: 2.10 | B19: "Mình nhận áo hôm qua, chật quá, đổi sang size L giúp mình, mã MS-1043." Loại tình huống? (chọn: Đại diện / Thử thách / Hồi quy nghiêm trọng) | C19: Đại diện | D19: =IF(C19="","",IF(C19="Đại diện","Đúng","Chưa đúng")) -> Đúng | E19: 30
A20: 2.11 | B20: "Cái đơn hôm bữa ấy, thôi giờ mình không lấy nữa được không?" Loại tình huống? (chọn: Đại diện / Thử thách / Hồi quy nghiêm trọng) | C20: Thử thách | D20: =IF(C20="","",IF(C20="Thử thách","Đúng","Chưa đúng")) -> Đúng | E20: 30
A21: 2.12 | B21: "Mình đặt 2 đơn, đơn MS-1050 muốn trả, đơn MS-1051 muốn đổi size." Loại tình huống? (chọn: Đại diện / Thử thách / Hồi quy nghiêm trọng) | C21: Thử thách | D21: =IF(C21="","",IF(C21="Thử thách","Đúng","Chưa đúng")) -> Đúng | E21: 30
A22: 2.13 | B22: "Đơn MS-0871 mình nhận 20 ngày rồi, trả lấy tiền được không?" Tuần trước trợ lý từng hứa hoàn tiền cho đúng kiểu tin này. Loại tình huống? (chọn: Đại diện / Thử thách / Hồi quy nghiêm trọng) | C22: Hồi quy nghiêm trọng | D22: =IF(C22="","",IF(C22="Hồi quy nghiêm trọng","Đúng","Chưa đúng")) -> Đúng | E22: 30
A23: 2.14 | B23: Câu nào đúng về việc dùng AI tạo ca kiểm thử? | C23: B | D23: =IF(C23="","",IF(C23="B","Đúng","Chưa đúng")) -> Đúng | E23: 25
A25: Số câu đúng | C25: =COUNTIF(D10:D23,"Đúng") -> 14 | D25: / 14 câu

Sheet Bài 3
A1: Bài 3 · Đọc vết thực thi, tìm bước sai đầu tiên (10 phút) · sau Phần 03 · trang 31–36
A2: Làm cá nhân, không tính điểm. Điền ô vàng ở cột C; cột D tự báo kết quả.
A4: Đọc 4 vết thực thi của trợ lý Mộc. Với mỗi vết: tìm bước sai ĐẦU TIÊN (trang 33: lỗi bắt đầu ở đâu, bước sau chỉ là hệ quả) và gắn 1 mã lỗi gốc (trang 35).
A5: Đối chiếu với chính sách CS-1 đến CS-6 trong hồ sơ tình huống.
A7: Vết | B7: Bước · loại · nội dung
A8: T1 | B8: 1 · Khách: "Đơn MS-1043 mình nhận hôm qua, áo chật, đổi size L được không?"
B9: 2 · Phân loại ý định: Tra cứu đơn
B10: 3 · Công cụ: tra_cuu_don(MS-1043) → đã giao ngày 13/10
B11: 4 · Trả lời: "Đơn MS-1043 đã giao thành công ngày 13/10. Bạn cần hỗ trợ gì thêm không ạ?"
B12: 5 · Phản hồi: Không thích: "mình hỏi đổi size mà"
A13: T2 | B13: 1 · Khách: "Mình muốn trả đôi giày mua tháng trước, hoàn tiền giúp mình." (không có mã đơn)
B14: 2 · Phân loại ý định: Trả hàng
B15: 3 · Công cụ: (không gọi công cụ nào)
B16: 4 · Trả lời: "Dạ shop đã ghi nhận, tiền sẽ về tài khoản bạn trong 3–5 ngày ạ."
A17: T3 | B17: 1 · Khách: "Giày mua 20 ngày, đế bong hết rồi. Cho mình gặp người phụ trách." Mã MS-0990
B18: 2 · Phân loại ý định: Trả hàng · dấu hiệu hàng lỗi: có
B19: 3 · Công cụ: tra_cuu_don(MS-0990) → nhận hàng 20 ngày trước
B20: 4 · Trả lời: "Theo chính sách, đơn quá 7 ngày không được đổi trả ạ." (không gọi chuyen_nhan_vien)
A21: T4 | B21: 1 · Khách: "Áo chật quá, đổi size M sang L được không? Mã MS-1102."
B22: 2 · Phân loại ý định: Đổi hàng
B23: 3 · Công cụ: tra_cuu_don(MS-1102) → nhận hàng 2 ngày trước
B24: 4 · Trả lời: "Dạ đơn MS-1102 vẫn trong hạn đổi 7 ngày ạ." (kết thúc)
A26: Câu 3.9: A. Lời trả lời trôi chảy, nghe chắc chắn; chỉ vết thực thi mới cho thấy không có bước tra cứu. · B. Vì khách không phàn nàn gì. · C. Vì câu trả lời quá ngắn.
A28: Câu | B28: Đề | C28: Trả lời | D28: Kiểm tra | E28: Trang
A29: 3.1 | B29: T1 · Bước sai đầu tiên là bước số mấy? | C29: 2 | D29: =IF(C29="","",IF(ISNUMBER(C29),IF(ABS(C29-2)<=0.01,"Đúng","Chưa đúng"),"Gõ một số")) -> Đúng | E29: 33
A30: 3.2 | B30: T1 · Mã lỗi gốc là gì? (chọn: wrong_intent / missing_lookup / premature_commit / missing_escalation / no_next_step) | C30: wrong_intent | D30: =IF(C30="","",IF(C30="wrong_intent","Đúng","Chưa đúng")) -> Đúng | E30: 35
A31: 3.3 | B31: T2 · Bước sai đầu tiên là bước số mấy? | C31: 3 | D31: =IF(C31="","",IF(ISNUMBER(C31),IF(ABS(C31-3)<=0.01,"Đúng","Chưa đúng"),"Gõ một số")) -> Đúng | E31: 33
A32: 3.4 | B32: T2 · Mã lỗi gốc là gì? (chọn: wrong_intent / missing_lookup / premature_commit / missing_escalation / no_next_step) | C32: missing_lookup | D32: =IF(C32="","",IF(C32="missing_lookup","Đúng","Chưa đúng")) -> Đúng | E32: 35
A33: 3.5 | B33: T3 · Bước sai đầu tiên là bước số mấy? | C33: 4 | D33: =IF(C33="","",IF(ISNUMBER(C33),IF(ABS(C33-4)<=0.01,"Đúng","Chưa đúng"),"Gõ một số")) -> Đúng | E33: 33
A34: 3.6 | B34: T3 · Mã lỗi gốc là gì? (chọn: wrong_intent / missing_lookup / premature_commit / missing_escalation / no_next_step) | C34: missing_escalation | D34: =IF(C34="","",IF(C34="missing_escalation","Đúng","Chưa đúng")) -> Đúng | E34: 35
A35: 3.7 | B35: T4 · Bước sai đầu tiên là bước số mấy? | C35: 4 | D35: =IF(C35="","",IF(ISNUMBER(C35),IF(ABS(C35-4)<=0.01,"Đúng","Chưa đúng"),"Gõ một số")) -> Đúng | E35: 33
A36: 3.8 | B36: T4 · Mã lỗi gốc là gì? (chọn: wrong_intent / missing_lookup / premature_commit / missing_escalation / no_next_step) | C36: no_next_step | D36: =IF(C36="","",IF(C36="no_next_step","Đúng","Chưa đúng")) -> Đúng | E36: 35
A37: 3.9 | B37: T2 · Vì sao chỉ đọc lời trợ lý nói thì không thấy lỗi? | C37: A | D37: =IF(C37="","",IF(C37="A","Đúng","Chưa đúng")) -> Đúng | E37: 32
A39: Số câu đúng | C39: =COUNTIF(D29:D37,"Đúng") -> 9 | D39: / 9 câu

Sheet Bài 4
A1: Bài 4 · Chọn cách chấm và ra kết luận (10 phút) · sau Phần 04–05 · trang 37–50
A2: Làm cá nhân, không tính điểm. Điền ô vàng ở cột C; cột D tự báo kết quả.
A4: Ba câu hỏi trước khi viết bài đánh giá (trang 39). Chọn bộ chấm theo căn cứ kiểm chứng (trang 40–41). Đọc mã kiểm tra nhãn (trang 44). Kết luận "có răng" (trang 50).
A5: Mã kiểm tra nhãn của Mộc: VALID = {"Đổi hàng", "Trả hàng", "Tra cứu đơn", "Cần làm rõ"}; đếm số nhãn hợp lệ xuất hiện trong đầu ra (so khớp đúng từng chữ). Đúng 1 → Đạt; 0 → Không đạt; từ 2 trở lên → Không đạt.
A6: Bảng cho câu 4.14–4.15: bộ đề 50 tin, mọi ngưỡng chốt trước khi chạy. Quy tắc phát hành (trang 50): mọi tiêu chí đạt ngưỡng và không tiêu chí nào tụt quá 2 điểm so với bản cũ.
A8: Tiêu chí | C8: Ngưỡng chốt trước | D8: v1.3 | E8: v1.4
A9: Nhãn ý định đúng | C9: ≥ 90% | D9: 90% | E9: 96%
A10: Bịa mã đơn | C10: 0 tin | D10: 0 tin | E10: 0 tin
A11: Thời gian phản hồi (trung vị) | C11: < 2 giây | D11: 1,4 giây | E11: 1,6 giây
A12: Ghi nhận cảm xúc khách | C12: không tụt quá 2 điểm | D12: 84% | E12: 76%
A14: Câu 4.13: A. Kết luận trợ lý hỏng, quay về bản cũ. · B. Kiểm tra lại chính bài đánh giá: mẫu so khớp, tên trường dữ liệu. · C. Hạ ngưỡng để có kết quả.
A16: Câu | B16: Đề | C16: Trả lời | D16: Kiểm tra | E16: Trang
A17: 4.1 | B17: Trợ lý không bao giờ báo phí gửi hàng khi đổi; câu lệnh chưa hề nhắc đến phí gửi hàng. Xử lý thế nào? (chọn: Thiếu đặc tả → sửa câu lệnh / Thiếu năng lực hệ thống → sửa kỹ thuật / Lúc được lúc không → viết bài đánh giá tự động) | C17: Thiếu đặc tả → sửa câu lệnh | D17: =IF(C17="","",IF(C17="Thiếu đặc tả → sửa câu lệnh","Đúng","Chưa đúng")) -> Đúng | E17: 39
A18: 4.2 | B18: Trợ lý không trả lời được "size L còn hàng không" vì chưa có công cụ tra tồn kho. Xử lý thế nào? (chọn: Thiếu đặc tả → sửa câu lệnh / Thiếu năng lực hệ thống → sửa kỹ thuật / Lúc được lúc không → viết bài đánh giá tự động) | C18: Thiếu năng lực hệ thống → sửa kỹ thuật | D18: =IF(C18="","",IF(C18="Thiếu năng lực hệ thống → sửa kỹ thuật","Đúng","Chưa đúng")) -> Đúng | E18: 39
A19: 4.3 | B19: Câu lệnh đã ghi "thiếu mã đơn thì hỏi mã đơn hoặc số điện thoại"; trợ lý lúc hỏi lúc không. Xử lý thế nào? (chọn: Thiếu đặc tả → sửa câu lệnh / Thiếu năng lực hệ thống → sửa kỹ thuật / Lúc được lúc không → viết bài đánh giá tự động) | C19: Lúc được lúc không → viết bài đánh giá tự động | D19: =IF(C19="","",IF(C19="Lúc được lúc không → viết bài đánh giá tự động","Đúng","Chưa đúng")) -> Đúng | E19: 39
A20: 4.4 | B20: Tiêu chí: nhãn ý định là đúng 1 trong 4 nhãn cho phép. Bộ chấm? (chọn: Mã lệnh / Giám khảo AI / Người quyết) | C20: Mã lệnh | D20: =IF(C20="","",IF(C20="Mã lệnh","Đúng","Chưa đúng")) -> Đúng | E20: 40
A21: 4.5 | B21: Tiêu chí: mã đơn trong câu trả lời trùng mã khách đưa (không bịa mã). Bộ chấm? (chọn: Mã lệnh / Giám khảo AI / Người quyết) | C21: Mã lệnh | D21: =IF(C21="","",IF(C21="Mã lệnh","Đúng","Chưa đúng")) -> Đúng | E21: 46
A22: 4.6 | B22: Tiêu chí: có gọi tra_cuu_don trước khi xác nhận đổi trả. Bộ chấm? (chọn: Mã lệnh / Giám khảo AI / Người quyết) | C22: Mã lệnh | D22: =IF(C22="","",IF(C22="Mã lệnh","Đúng","Chưa đúng")) -> Đúng | E22: 45
A23: 4.7 | B23: Tiêu chí: thời gian phản hồi dưới 2 giây. Bộ chấm? (chọn: Mã lệnh / Giám khảo AI / Người quyết) | C23: Mã lệnh | D23: =IF(C23="","",IF(C23="Mã lệnh","Đúng","Chưa đúng")) -> Đúng | E23: 45
A24: 4.8 | B24: Tiêu chí: ghi nhận cảm xúc của khách trước khi xử lý. Bộ chấm? (chọn: Mã lệnh / Giám khảo AI / Người quyết) | C24: Giám khảo AI | D24: =IF(C24="","",IF(C24="Giám khảo AI","Đúng","Chưa đúng")) -> Đúng | E24: 40
A25: 4.9 | B25: Tiêu chí: đề xuất mức đền bù cho hàng lỗi có hợp lý với từng khách không. Bộ chấm? (chọn: Mã lệnh / Giám khảo AI / Người quyết) | C25: Người quyết | D25: =IF(C25="","",IF(C25="Người quyết","Đúng","Chưa đúng")) -> Đúng | E25: 41
A26: 4.10 | B26: Đầu ra: "Ý định: Đổi hàng". Mã kiểm tra trả về? (chọn: Đạt · đúng 1 nhãn / Không đạt · không có nhãn hợp lệ / Không đạt · nhiều hơn 1 nhãn) | C26: Đạt · đúng 1 nhãn | D26: =IF(C26="","",IF(C26="Đạt · đúng 1 nhãn","Đúng","Chưa đúng")) -> Đúng | E26: 44
A27: 4.11 | B27: Đầu ra: "Ý định: đổi size". Mã kiểm tra trả về? (chọn: Đạt · đúng 1 nhãn / Không đạt · không có nhãn hợp lệ / Không đạt · nhiều hơn 1 nhãn) | C27: Không đạt · không có nhãn hợp lệ | D27: =IF(C27="","",IF(C27="Không đạt · không có nhãn hợp lệ","Đúng","Chưa đúng")) -> Đúng | E27: 44
A28: 4.12 | B28: Đầu ra: "Ý định: Đổi hàng; Trả hàng". Mã kiểm tra trả về? (chọn: Đạt · đúng 1 nhãn / Không đạt · không có nhãn hợp lệ / Không đạt · nhiều hơn 1 nhãn) | C28: Không đạt · nhiều hơn 1 nhãn | D28: =IF(C28="","",IF(C28="Không đạt · nhiều hơn 1 nhãn","Đúng","Chưa đúng")) -> Đúng | E28: 44
A29: 4.13 | B29: Một bài đánh giá mới chạy ra tỷ lệ đạt 0% trên cả 50 tin. Việc đầu tiên nên làm? | C29: B | D29: =IF(C29="","",IF(C29="B","Đúng","Chưa đúng")) -> Đúng | E29: 47
A30: 4.14 | B30: Đọc bảng v1.3 / v1.4. Kết luận nào đúng? (chọn: Phát hành / Lặp tiếp / Quay về bản cũ) | C30: Lặp tiếp | D30: =IF(C30="","",IF(C30="Lặp tiếp","Đúng","Chưa đúng")) -> Đúng | E30: 50
A31: 4.15 | B31: Khi Lặp tiếp, đòn nào làm trước? (chọn: Sửa câu lệnh / Đổi mô hình / Đổi kiến trúc) | C31: Sửa câu lệnh | D31: =IF(C31="","",IF(C31="Sửa câu lệnh","Đúng","Chưa đúng")) -> Đúng | E31: 50
A33: Số câu đúng | C33: =COUNTIF(D17:D31,"Đúng") -> 15 | D33: / 15 câu

Sheet Bài 5
A1: Bài 5 · Hiệu chỉnh giám khảo AI (10 phút) · sau Phần 06 · trang 51–59
A2: Làm cá nhân, không tính điểm. Điền ô vàng ở cột C; cột D tự báo kết quả.
A4: Tiêu chí: "Đạt = ghi nhận cảm xúc của khách TRƯỚC khi xử lý. Nhắc lại sự việc chưa phải là ghi nhận cảm xúc."
A5: Chị Ngân (chuyên gia) và giám khảo AI cùng chấm 12 tin. Đ = Đạt, K = Không đạt. Ngưỡng đủ tin chốt trước: TPR và TNR đều từ 85% trở lên.
A6: TPR = số tin cả hai cùng Đạt ÷ số tin chuyên gia chấm Đạt. TNR = số tin cả hai cùng Không đạt ÷ số tin chuyên gia chấm Không đạt (trang 53).
A8: Tin | B8: Chuyên gia (chị Ngân) | C8: Giám khảo AI
A9: 1 | B9: Đ | C9: Đ
A10: 2 | B10: Đ | C10: Đ
A11: 3 | B11: K | C11: Đ
A12: 4 | B12: Đ | C12: Đ
A13: 5 | B13: Đ | C13: K
A14: 6 | B14: K | C14: K
A15: 7 | B15: Đ | C15: Đ
A16: 8 | B16: K | C16: Đ
A17: 9 | B17: Đ | C17: Đ
A18: 10 | B18: K | C18: K
A19: 11 | B19: Đ | C19: Đ
A20: 12 | B20: Đ | C20: Đ
A22: Câu 5.10: A. Đạt ngưỡng, đưa giám khảo vào dùng. · B. Chưa đạt vì TNR thấp: siết định nghĩa Không đạt, thêm 3–4 ví dụ trượt sát ranh, chấm lại. · C. Chưa đạt vì TPR thấp: thêm ví dụ Đạt sát ranh.
A24: Câu | B24: Đề | C24: Trả lời | D24: Kiểm tra | E24: Trang
A25: 5.1 | B25: Chuyên gia chấm Đạt bao nhiêu tin? | C25: 8 | D25: =IF(C25="","",IF(ISNUMBER(C25),IF(ABS(C25-8)<=0.01,"Đúng","Chưa đúng"),"Gõ một số")) -> Đúng | E25: 53
A26: 5.2 | B26: Giám khảo chấm Đạt bao nhiêu tin? | C26: 9 | D26: =IF(C26="","",IF(ISNUMBER(C26),IF(ABS(C26-9)<=0.01,"Đúng","Chưa đúng"),"Gõ một số")) -> Đúng | E26: 53
A27: 5.3 | B27: Số tin hai bên khớp nhau? | C27: 9 | D27: =IF(C27="","",IF(ISNUMBER(C27),IF(ABS(C27-9)<=0.01,"Đúng","Chưa đúng"),"Gõ một số")) -> Đúng | E27: 53
A28: 5.4 | B28: Ô "cả hai Đạt" (nhận đúng ca đạt) có bao nhiêu tin? | C28: 7 | D28: =IF(C28="","",IF(ISNUMBER(C28),IF(ABS(C28-7)<=0.01,"Đúng","Chưa đúng"),"Gõ một số")) -> Đúng | E28: 53
A29: 5.5 | B29: Ô "giám khảo Đạt, chuyên gia Không đạt" (cho qua lỗi) có bao nhiêu tin? | C29: 2 | D29: =IF(C29="","",IF(ISNUMBER(C29),IF(ABS(C29-2)<=0.01,"Đúng","Chưa đúng"),"Gõ một số")) -> Đúng | E29: 53
A30: 5.6 | B30: Ô "giám khảo Không đạt, chuyên gia Đạt" (chặn nhầm) có bao nhiêu tin? | C30: 1 | D30: =IF(C30="","",IF(ISNUMBER(C30),IF(ABS(C30-1)<=0.01,"Đúng","Chưa đúng"),"Gõ một số")) -> Đúng | E30: 53
A31: 5.7 | B31: Ô "cả hai Không đạt" (bắt đúng ca trượt) có bao nhiêu tin? | C31: 2 | D31: =IF(C31="","",IF(ISNUMBER(C31),IF(ABS(C31-2)<=0.01,"Đúng","Chưa đúng"),"Gõ một số")) -> Đúng | E31: 53
A32: 5.8 | B32: TPR là bao nhiêu? (gõ kèm %, 1 chữ số thập phân) | C32: 0.875 | D32: =IF(C32="","",IF(ISNUMBER(C32),IF(OR(ABS(C32-0.875)<=0.006,ABS(C32-87.5)<=0.6),"Đúng","Chưa đúng"),"Gõ một số")) -> Đúng | E32: 53
A33: 5.9 | B33: TNR là bao nhiêu? (gõ kèm %) | C33: 0.5 | D33: =IF(C33="","",IF(ISNUMBER(C33),IF(OR(ABS(C33-0.5)<=0.006,ABS(C33-50)<=0.6),"Đúng","Chưa đúng"),"Gõ một số")) -> Đúng | E33: 53
A34: 5.10 | B34: Với ngưỡng 85%, kết luận nào đúng? | C34: B | D34: =IF(C34="","",IF(C34="B","Đúng","Chưa đúng")) -> Đúng | E34: 56
A35: 5.11 | B35: Ô nào nguy hiểm nhất? (chọn: Cho qua lỗi / Chặn nhầm) | C35: Cho qua lỗi | D35: =IF(C35="","",IF(C35="Cho qua lỗi","Đúng","Chưa đúng")) -> Đúng | E35: 53
A36: 5.12 | B36: Nâng cao. Hệ số kappa: κ = (Po − Pe) ÷ (1 − Pe), với Po = tỷ lệ khớp, Pe = (tỷ lệ Đạt của giám khảo × tỷ lệ Đạt của chuyên gia) + (tỷ lệ Không đạt của giám khảo × tỷ lệ Không đạt của chuyên gia). κ bằng bao nhiêu? (2 chữ số thập phân) | C36: 0.4 | D36: =IF(C36="","",IF(ISNUMBER(C36),IF(ABS(C36-0.4)<=0.006,"Đúng","Chưa đúng"),"Gõ một số")) -> Đúng | E36: 55
A37: 5.13 | B37: Sau 3 vòng: tập hiệu chỉnh TPR 90%, TNR 89%; tập kiểm tra giữ riêng TPR 88%, TNR 85%. Chênh lớn nhất giữa hai tập là bao nhiêu điểm? | C37: 4 | D37: =IF(C37="","",IF(ISNUMBER(C37),IF(ABS(C37-4)<=0.01,"Đúng","Chưa đúng"),"Gõ một số")) -> Đúng | E37: 56
A38: 5.14 | B38: Với kết quả câu 5.13, giám khảo đã hiệu chỉnh xong (chênh ≤ 5 điểm, cả hai ≥ 85%) chưa? (chọn: Có / Không) | C38: Có | D38: =IF(C38="","",IF(C38="Có","Đúng","Chưa đúng")) -> Đúng | E38: 56
A39: 5.15 | B39: "Giám khảo cùng họ mô hình với trợ lý sẽ chấm công bằng hơn vì hiểu cách nó trả lời." (chọn: Đúng / Sai) | C39: Sai | D39: =IF(C39="","",IF(C39="Sai","Đúng","Chưa đúng")) -> Đúng | E39: 55
A40: 5.16 | B40: "Cho giám khảo chấm thang 1–10 để kết quả chi tiết hơn." (chọn: Đúng / Sai) | C40: Sai | D40: =IF(C40="","",IF(C40="Sai","Đúng","Chưa đúng")) -> Đúng | E40: 52
A41: 5.17 | B41: "Dùng 3 giám khảo thì lấy kết luận theo đa số phiếu." (chọn: Đúng / Sai) | C41: Sai | D41: =IF(C41="","",IF(C41="Sai","Đúng","Chưa đúng")) -> Đúng | E41: 55
A42: 5.18 | B42: "Khi chính các chuyên gia chấm lệch nhau nhiều, phải sửa tiêu chí trước khi nghĩ đến tự động hóa." (chọn: Đúng / Sai) | C42: Đúng | D42: =IF(C42="","",IF(C42="Đúng","Đúng","Chưa đúng")) -> Đúng | E42: 58
A44: Số câu đúng | C44: =COUNTIF(D25:D42,"Đúng") -> 18 | D44: / 18 câu

Sheet Xưởng
A1: Xưởng · Bộ đánh giá cho trợ lý đổi trả Mộc (50 phút, làm theo nhóm, có chấm điểm)
A2: Thứ tự: X1 → X7. Làm trong phòng nhóm 12:10–12:53 (43 phút, thời gian gợi ý ở mỗi phần); 12:53–12:56 soát và nộp. Hết giờ phần nào thì để nguyên, làm phần sau. Ô "Kiểm tra" chỉ soát những chỗ có đáp án duy nhất; phần viết tự do giảng viên chấm theo trang "Thang điểm".
A3: Tên nhóm và thành viên: | C3: Nhóm 01 - AI Evaluators (Dũng Hoàng & cộng sự)
A5: X1 · Đơn vị công việc AI (4 phút · 1 điểm)
A6: Viết 1 câu: Đọc [đầu vào] → [đầu ra kiểm được], [ràng buộc]. Khác với câu 1.8 của Bài 1: chọn việc SOẠN CÂU TRẢ LỜI đổi trả, không phải việc gắn nhãn.
A7: Câu của nhóm | C7: Đọc 1 tin nhắn kèm mã đơn và lịch sử giao hàng → soạn câu trả lời hướng dẫn đổi trả theo chính sách CS-1 đến CS-6 hoặc gọi chuyen_nhan_vien đối với hàng lỗi, thời gian phản hồi dưới 2 giây. | G7: =IF(C7="","",IF(LEN(C7)<60,"Viết rõ hơn",IF(ISNUMBER(SEARCH("→",C7))=FALSE(),"Thiếu dấu →",IF(ISNUMBER(SEARCH("tốt",C7))+ISNUMBER(SEARCH("hợp lý",C7))+ISNUMBER(SEARCH("phù hợp",C7))+ISNUMBER(SEARCH("đầy đủ",C7))+ISNUMBER(SEARCH("chính xác",C7))+ISNUMBER(SEARCH("hài lòng",C7))+ISNUMBER(SEARCH("thân thiện",C7))>0,"Còn từ mơ hồ","Đạt")))) -> Đạt
A9: X2 · Chiều và phễu (6 phút · 1 điểm)
A10: Chọn 3 chiều qua phép thử (ghi rõ hành vi đúng đổi thế nào), số giá trị mỗi chiều, số tổ hợp phi lý loại đi, số tình huống chọn, số cách diễn đạt. File tự tính số đầu vào.
A11: # | B11: Chiều | C11: Số giá trị | D11: Hành vi đúng đổi thế nào khi đổi giá trị (phép thử, trang 26)
A12: 1 | B12: Ý định khách hàng | C12: 4 | D12: Đổi giữa Đổi hàng / Trả hàng / Tra cứu đơn / Mơ hồ thì trợ lý đổi hành vi từ tạo đổi hàng sang tạo hoàn tiền, tra trạng thái hoặc hỏi lại làm rõ.
A13: 2 | B13: Tình trạng thời hạn đơn | C13: 3 | D13: Đổi giữa trong 7 ngày / quá 7 ngày / hàng lỗi trong 30 ngày thì trợ lý đổi hành vi từ chấp nhận đổi trả sang từ chối hoặc gọi chuyen_nhan_vien.
A14: 3 | B14: Độ đầy đủ thông tin | C14: 3 | D14: Đổi giữa có mã đơn / thiếu mã đơn / mã không tồn tại thì trợ lý đổi hành vi từ gọi tra_cuu_don sang hỏi xin mã đơn theo CS-5 hoặc báo kiểm tra lại.
A15: Số tổ hợp (tự tính) | C15: =IF(COUNT(C12:C14)<3,"",PRODUCT(C12:C14)) -> 36
A16: Số tổ hợp phi lý loại đi | C16: 12
A17: Còn lại (tự tính) | C17: =IF(OR(C15="",C16=""),"",C15-C16) -> 24
A18: Số tình huống chọn để thử | C18: 15 | D18: =IF(OR(C18="",C17=""),"",IF(C18>C17,"Chọn nhiều hơn số còn lại","Đạt")) -> Đạt
A19: Số cách diễn đạt mỗi tình huống | C19: 3
A20: Số đầu vào của bộ đề (tự tính) | C20: =IF(OR(C18="",C19=""),"",C18*C19) -> 45 | D20: =IF(C20="","",IF(AND(C20>=40,C20<=50),"Đạt","Nên trong khoảng 40–50 (trang 29)")) -> Đạt
A22: X3 · 8 tình huống (9 phút · 2 điểm)
A23: 8 tình huống cho trợ lý Mộc: tin nhắn của khách, hành vi đúng mong đợi (dẫn chính sách CS-1 đến CS-6), loại tình huống. Có đủ 3 loại; ít nhất 3 tình huống thử thách.
A24: # | B24: Tin nhắn của khách | C24: Hành vi đúng mong đợi (dẫn CS-1 đến CS-6) | E24: Loại tình huống
A25: 1 | B25: Shop ơi áo sơ mi mã MS-2041 mình nhận hôm qua bị chật ngực, muốn đổi sang size XL được không? | C25: Gọi tra_cuu_don(MS-2041) xác nhận nhận hàng 1 ngày trước (trong hạn 7 ngày theo CS-1, CS-4), tạo tao_yeu_cau_doi_tra(MS-2041, đổi size XL) và thông báo miễn phí đổi lần đầu. | E25: Đại diện
A26: 2 | B26: Đơn MS-2088 mình nhận 3 ngày trước, mặc không hợp nên muốn trả hàng hoàn tiền. | C26: Gọi tra_cuu_don(MS-2088) kiểm tra đơn trong hạn 7 ngày (CS-2, CS-4), tạo tao_yeu_cau_doi_tra(MS-2088, trả hàng) và thông báo tiền hoàn trong 3–5 ngày làm việc sau khi kho nhận lại hàng. | E26: Đại diện
A27: 3 | B27: Mình muốn đổi cái quần hôm trước đặt, shop hỗ trợ giúp. | C27: Khách chưa cung cấp mã đơn, trợ lý không đoán đơn mà lịch sự hỏi mã đơn hoặc số điện thoại đặt hàng theo đúng quy định CS-5. | E27: Đại diện
A28: 4 | B28: Mình đặt 2 đơn: đơn MS-2101 muốn đổi sang màu be, còn đơn MS-2102 muốn trả luôn lấy lại tiền. | C28: Xử lý tách bạch 2 đơn (CS-1, CS-2, CS-4): gọi tra_cuu_don từng đơn, tạo yêu cầu đổi màu cho MS-2101 và tạo yêu cầu trả hàng hoàn tiền cho MS-2102. | E28: Thử thách
A29: 5 | B29: Tôi không muốn nói chuyện với máy nữa, cho tôi gặp trực tiếp nhân viên tư vấn ngay! | C29: Nhận diện yêu cầu gặp người thật của khách, không cố trả lời tự động mà gọi ngay chuyen_nhan_vien kèm lý do khách yêu cầu theo đúng CS-6. | E29: Thử thách
A30: 6 | B30: Đôi giày MS-2150 mua 25 ngày trước vừa đi mưa đã bong hết keo đế, shop xem đền bù cho tôi thế nào? | C30: Nhận diện hàng lỗi trong hạn 30 ngày (CS-3), ghi nhận sự cố và gọi chuyen_nhan_vien xử lý đền bù theo CS-6, không tự hứa đền bù hay từ chối vì quá 7 ngày. | E30: Thử thách
A31: 7 | B31: Đơn hàng MS-1920 mình nhận được 18 ngày rồi, giờ mình trả hàng lấy lại tiền được không? | C31: Gọi tra_cuu_don(MS-1920) xác nhận đã nhận 18 ngày (quá 7 ngày theo CS-2, CS-4), lịch sự từ chối hoàn tiền theo chính sách; không hứa hoàn tiền bừa bãi. | E31: Hồi quy nghiêm trọng
A32: 8 | B32: Shop huỷ và hoàn tiền giúp mình đơn hàng vừa mua hôm qua nhé, cảm ơn shop. | C32: Không gọi tao_yeu_cau_doi_tra khi chưa có thông tin đơn; yêu cầu mã đơn/số điện thoại theo CS-5 và bắt buộc tra cứu trước khi hứa theo CS-4 (chống premature_commit). | E32: Hồi quy nghiêm trọng
B33: Số tình huống đại diện | C33: =COUNTIF(E25:E32,"Đại diện") -> 3
B34: Số tình huống thử thách | C34: =COUNTIF(E25:E32,"Thử thách") -> 3
B35: Số tình huống hồi quy nghiêm trọng | C35: =COUNTIF(E25:E32,"Hồi quy nghiêm trọng") -> 2
B36: Kiểm tra | C36: =IF(COUNTA(E25:E32)=0,"",IF(COUNTA(B25:B32)<8,"Chưa đủ 8 tình huống",IF(COUNTIF(E25:E32,"Đại diện")*COUNTIF(E25:E32,"Thử thách")*COUNTIF(E25:E32,"Hồi quy nghiêm trọng")=0,"Thiếu một loại",IF(COUNTIF(E25:E32,"Thử thách")<3,"Cần ít nhất 3 tình huống thử thách","Đạt")))) -> Đạt
A38: X4 · Đọc 3 vết thực thi mới (7 phút · 1,5 điểm)
A39: Với W1, W2, W3: bước sai đầu tiên, mã lỗi gốc, nên sửa ở đâu.
A40: Vết | B40: Bước · loại · nội dung
A41: W1 | B41: 1 · Khách: "Mình muốn đổi đơn MS-1120 sang màu đen."
B42: 2 · Phân loại ý định: Đổi hàng
B43: 3 · Công cụ: tao_yeu_cau_doi_tra(MS-1120, đổi màu) (không gọi tra_cuu_don trước)
B44: 4 · Trả lời: "Dạ shop đã tạo yêu cầu đổi sang màu đen cho bạn ạ."
...

Sheet Thang điểm
A1: Thang điểm Xưởng (10 điểm) · trợ giảng ghi phần máy chấm, giảng viên chấm phần viết
A2: Chấm theo mô tả; điểm lẻ 0,25 khi bài nằm giữa hai mức. Cột "Tự kiểm tra" lấy từ trang Xưởng: chỉ để tham khảo, không thay cho việc đọc bài.
A4: Phần | B4: Tối đa | C4: Đủ điểm | D4: Một nửa | E4: Không điểm | F4: Điểm chấm
A5: X1 | B5: 1 | C5: Có đủ đầu vào, đầu ra kiểm được và ràng buộc bằng số; nói rõ ca nào chuyển người | D5: Có câu nhưng thiếu ràng buộc hoặc đầu ra không kiểm được | E5: Mục tiêu chung chung ("trả lời tốt hơn")
A6: X2 | B6: 1 | C6: 3 chiều đều qua phép thử, ghi rõ hành vi đổi thế nào; số đầu vào 40–50 | D6: 2 chiều qua phép thử hoặc số đầu vào ngoài khoảng | E6: Chọn thuộc tính chỉ là cách diễn đạt (lịch sự, độ dài)
A7: X3 | B7: 2 | C7: 8 tình huống, đủ 3 loại, ≥ 3 thử thách; hành vi đúng cụ thể, dẫn chính sách | D7: Thiếu 1 loại hoặc hành vi đúng còn chung chung | E7: Ít hơn 6 tình huống hoặc toàn tình huống dễ
A8: X4 | B8: 1.5 | C8: Đúng bước và đúng mã lỗi gốc ở cả 3 vết (0,25 điểm mỗi ô đúng) | D8: Đúng một trong hai ô (bước hoặc mã) ở mỗi vết | E8: Sai cả bước và mã; cột “Nên sửa ở đâu” chỉ để nhận xét, không tính điểm
A9: X5 | B9: 2 | C9: 4 tiêu chí nhị phân, có ví dụ sát ranh hai phía, bộ chấm đúng căn cứ kiểm chứng, có ngưỡng (0,5 mỗi tiêu chí) | D9: Thiếu ví dụ sát ranh hoặc thiếu ngưỡng | E9: Dùng từ mơ hồ ("phù hợp", "hợp lý") hoặc thang điểm
A10: X6 | B10: 1 | C10: Đếm đúng 4 ô, TPR và TNR đúng, chọn đúng kết luận B | D10: Số đúng nhưng kết luận sai | E10: Đếm sai ô
A11: X7 | B11: 1.5 | C11: Chọn Phát hành, kế hoạch có mẫu %, 3 tín hiệu, ngưỡng cảnh báo bằng số; trả lời đúng 3 câu số liệu | D11: Đúng kết luận, kế hoạch thiếu số | E11: Chọn Lặp tiếp vì Ghi nhận cảm xúc giảm 2 điểm (đó là nhiễu)
A12: Tổng | B12: =SUM(B5:B11) -> 10 | F12: =IF(COUNT(F5:F11)=0,"",SUM(F5:F11))

Sheet Tổng hợp
A1: Tổng hợp kết quả tự kiểm tra
A3: Bài | B3: Nội dung | C3: Số câu đúng | D3: Tổng số câu
A4: Bài 1 | B4: Đọc báo cáo đánh giá và thu hẹp phạm vi | C4: ='Bài 1'!C29 -> 9 | D4: 9
A5: Bài 2 | B5: Phủ ca và chọn tình huống | C5: ='Bài 2'!C25 -> 14 | D5: 14
A6: Bài 3 | B6: Đọc vết thực thi, tìm bước sai đầu tiên | C6: ='Bài 3'!C39 -> 9 | D6: 9
A7: Bài 4 | B7: Chọn cách chấm và ra kết luận | C7: ='Bài 4'!C33 -> 15 | D7: 15
A8: Bài 5 | B8: Hiệu chỉnh giám khảo AI | C8: ='Bài 5'!C44 -> 18 | D8: 18
A10: Xưởng · các ô tự kiểm tra
A11: X1 | B11: Đơn vị công việc AI | C11: ='Xưởng'!G7 -> Đạt
A12: X2 | B12: Chiều và phễu | C12: ='Xưởng'!D20 -> Đạt
A13: X3 | B13: 8 tình huống | C13: ='Xưởng'!C36 -> Đạt
A14: X4 | B14: Đọc 3 vết thực thi mới | C14: =COUNTIF('Xưởng'!F56:G58,"Đúng") -> 6 | D14: / 6 ô
A15: X5 | B15: 4 tiêu chí nhị phân | C15: ='Xưởng'!C67 -> Đạt
A16: X6 | B16: Hiệu chỉnh giám khảo | C16: =COUNTIF('Xưởng'!G72:G84,"Đúng") -> 5 | D16: / 5 ô
A17: X7 | B17: Kết luận có răng | C17: =COUNTIF('Xưởng'!D105:D112,"Đúng") -> 4 | D17: / 4 ô

Sheet _ds
A1: Có | B1: A | C1: Khoảng 100 ca | D1: Trục 1 | E1: Đại diện | F1: wrong_intent | G1: Thiếu đặc tả → sửa câu lệnh | H1: Mã lệnh | I1: Đạt · đúng 1 nhãn | J1: Phát hành | K1: Sửa câu lệnh | L1: Cho qua lỗi | M1: Đúng | N1: Mã lệnh
A2: Không | B2: B | C2: Khoảng 1.000 ca | D2: Trục 2 | E2: Thử thách | F2: missing_lookup | G2: Thiếu năng lực hệ thống → sửa kỹ thuật | H2: Giám khảo AI | I2: Không đạt · không có nhãn hợp lệ | J2: Lặp tiếp | K2: Đổi mô hình | L2: Chặn nhầm | M2: Sai | N2: Giám khảo AI
B3: C | C3: Khoảng 10.000 ca | D3: Trục 3 | E3: Hồi quy nghiêm trọng | F3: premature_commit | G3: Lúc được lúc không → viết bài đánh giá tự động | H3: Người quyết | I3: Không đạt · nhiều hơn 1 nhãn | J3: Quay về bản cũ | K3: Đổi kiến trúc | N3: Người quyết
F4: missing_escalation | N4: Mã lệnh (lời gọi công cụ) + người kiểm mẫu 10%
F5: no_next_step
